<?xml version="1.0" ?>
<!-- =================================================================================== -->
<!-- |    This document was autogenerated by xacro from whole_body.xacro               | -->
<!-- |    EDITING THIS FILE BY HAND IS NOT RECOMMENDED                                 | -->
<!-- =================================================================================== -->
<robot name="dual_arm">
  <gazebo>
    <plugin filename="/opt/ros/noetic/lib/libgazebo_ros_control.so" name="gazebo_ros_control">
      <robotNamespace>/</robotNamespace>
      <robotSimType>gazebo_ros_control/DefaultRobotHWSim</robotSimType>
      <legacyModeNS>true</legacyModeNS>
    </plugin>
  </gazebo>
  <!-- 世界坐标系配置 -->
  <link name="world"/>
  <joint name="x_dir_joint" type="prismatic">
    <parent link="world"/>
    <child link="x_dir_link"/>
    <origin rpy="0.0 0.0 0.0" xyz="0.0 0.0 0.0"/>
    <axis xyz="1 0 0"/>
    <limit effort="100" lower="-100" upper="100" velocity="50"/>
    <dynamics damping="0.0" friction="0.0"/>
  </joint>
  <link name="x_dir_link">
    <inertial>
      <mass value="0.1"/>
      <origin rpy="0 0 0" xyz="0 0 0"/>
      <inertia ixx="1.0" ixy="0.0" ixz="0.0" iyy="1.0" iyz="0.0" izz="1.0"/>
    </inertial>
  </link>
  <!-- y方向坐标系配置 -->
  <joint name="y_dir_joint" type="prismatic">
    <parent link="x_dir_link"/>
    <child link="y_dir_link"/>
    <origin rpy="0.0 0.0 0.0" xyz="0.0 0.0 0.0"/>
    <axis xyz="0 1 0"/>
    <limit effort="100" lower="-100" upper="100" velocity="50"/>
    <dynamics damping="0.0" friction="0.0"/>
  </joint>
  <link name="y_dir_link">
    <inertial>
      <mass value="0.1"/>
      <origin rpy="0 0 0" xyz="0 0 0"/>
      <inertia ixx="1.0" ixy="0.0" ixz="0.0" iyy="1.0" iyz="0.0" izz="1.0"/>
    </inertial>
  </link>
  <!-- z方向旋转配置 -->
  <joint name="z_dir_joint" type="revolute">
    <parent link="y_dir_link"/>
    <child link="mecanum_base"/>
    <origin rpy="0.0 0.0 0.0" xyz="0.0 0.0 0.0"/>
    <axis xyz="0 0 1"/>
    <limit effort="100" velocity="50" lower="-6283.185307179586" upper="6283.185307179586"/>
    <dynamics damping="0.0" friction="0.0"/>
  </joint>
  <link name="mecanum_base">
    <inertial>
      <origin rpy="0 0 0" xyz="-0.119770155106678 0.021524778789857 0.400959827297338"/>
      <mass value="153.654199495769"/>
      <inertia ixx="2.73031975440708" ixy="-0.000128859946414297" ixz="-0.00168093849971987" iyy="4.05163883336173" iyz="0.000607737842562367" izz="4.38778150528011"/>
    </inertial>
    <visual>
      <origin rpy="0 0 0" xyz="0 0 0"/>
      <geometry>
        <mesh filename="package://dual_arm/robot_description/meshes/base.dae"/>
      </geometry>
      <material name="">
        <color rgba="1 1 1 1"/>
      </material>
    </visual>
    <!-- <collision>
      <origin
        xyz="0 0 0"
        rpy="0 0 0" />
      <geometry>
        <mesh
          filename="package://dual_arm/robot_description/meshes/mecanum.stl" />
      </geometry>
    </collision> -->
  </link>

  <joint name="R_joint0" type="fixed">
    <parent link="mecanum_base"/>
    <child link="R_base_link"/>
    <origin rpy="1.5707963267948966 0 0" xyz="0.458231997984153 -0.146815895072947 1.2"/>
  </joint>
  <link name="R_base_link"/>
  <joint name="R_base_link-base_link_inertia" type="fixed">
    <parent link="R_base_link" />
    <child link="R_base_link_inertia" />
    <!-- 'base_link' is REP-103 aligned (so X+ forward), while the internal
          frames of the robot/controller have X+ pointing backwards.
          Use the joint between 'base_link' and 'base_link_inertia' (a dummy
          link/frame) to introduce the necessary rotation over Z (of pi rad).
    -->
    <origin xyz="0 0 0" rpy="0 0 -3.141592653589793" />
  </joint>
  <link name="R_base_link_inertia">
    <visual>
      <origin rpy="0 0 3.141592653589793" xyz="0 0 0"/>
      <geometry>
        <mesh filename="package://dual_arm/robot_description/meshes/visual/base.dae"/>
      </geometry>
      <material name="LightGrey">
        <color rgba="0.7 0.7 0.7 1.0"/>
      </material>
    </visual>
    <collision>
      <origin rpy="0 0 3.141592653589793" xyz="0 0 0"/>
      <geometry>
        <mesh filename="package://dual_arm/robot_description/meshes/collision/base.stl"/>
      </geometry>
    </collision>
    <inertial>
      <mass value="4.0"/>
      <origin rpy="0 0 0" xyz="0 0 0"/>
      <inertia ixx="0.0061063308908" ixy="0.0" ixz="0.0" iyy="0.0061063308908" iyz="0.0" izz="0.01125"/>
    </inertial>
  </link>
  <link name="R_shoulder_link">
    <visual>
      <origin rpy="0 0 3.141592653589793" xyz="0 0 0"/>
      <geometry>
        <mesh filename="package://dual_arm/robot_description/meshes/visual/shoulder.dae"/>
      </geometry>
      <material name="LightGrey">
        <color rgba="0.7 0.7 0.7 1.0"/>
      </material>
    </visual>
    <collision>
      <origin rpy="0 0 3.141592653589793" xyz="0 0 0"/>
      <geometry>
        <mesh filename="package://dual_arm/robot_description/meshes/collision/shoulder.stl"/>
      </geometry>
    </collision>
    <inertial>
      <mass value="7.369"/>
      <origin rpy="0 0 0" xyz="0 0 0"/>
      <inertia ixx="0.029819260655624295" ixy="0.0" ixz="0.0" iyy="0.029819260655624295" iyz="0.0" izz="0.020725312499999995"/>
    </inertial>
  </link>
  <link name="R_upper_arm_link">
    <visual>
      <origin rpy="1.5707963267948966 0 -1.5707963267948966" xyz="0 0 0.176"/>
      <geometry>
        <mesh filename="package://dual_arm/robot_description/meshes/visual/upperarm.dae"/>
      </geometry>
      <material name="LightGrey">
        <color rgba="0.7 0.7 0.7 1.0"/>
      </material>
    </visual>
    <collision>
      <origin rpy="1.5707963267948966 0 -1.5707963267948966" xyz="0 0 0.176"/>
      <geometry>
        <mesh filename="package://dual_arm/robot_description/meshes/collision/upperarm.stl"/>
      </geometry>
    </collision>
    <inertial>
      <mass value="10.45"/>
      <origin rpy="0 1.5707963267948966 0" xyz="-0.2392 0.0 0.175"/>
      <inertia ixx="0.21399985623335657" ixy="0.0" ixz="0.0" iyy="0.21399985623335657" iyz="0.0" izz="0.029390624999999997"/>
    </inertial>
  </link>
  <link name="R_forearm_link">
    <visual>
      <origin rpy="1.5707963267948966 0 -1.5707963267948966" xyz="0 0 0.04"/>
      <geometry>
        <mesh filename="package://dual_arm/robot_description/meshes/visual/forearm.dae"/>
      </geometry>
      <material name="LightGrey">
        <color rgba="0.7 0.7 0.7 1.0"/>
      </material>
    </visual>
    <collision>
      <origin rpy="1.5707963267948966 0 -1.5707963267948966" xyz="0 0 0.04"/>
      <geometry>
        <mesh filename="package://dual_arm/robot_description/meshes/collision/forearm.stl"/>
      </geometry>
    </collision>
    <inertial>
      <mass value="4.321"/>
      <origin rpy="0 1.5707963267948966 0" xyz="-0.18 0.0 0.04"/>
      <inertia ixx="0.052743185152717496" ixy="0.0" ixz="0.0" iyy="0.052743185152717496" iyz="0.0" izz="0.012152812499999997"/>
    </inertial>
  </link>
  <link name="R_wrist_1_link">
    <visual>
      <origin rpy="1.5707963267948966 0 0" xyz="0 0 -0.135"/>
      <geometry>
        <mesh filename="package://dual_arm/robot_description/meshes/visual/wrist1.dae"/>
      </geometry>
      <material name="LightGrey">
        <color rgba="0.7 0.7 0.7 1.0"/>
      </material>
    </visual>
    <collision>
      <origin rpy="1.5707963267948966 0 0" xyz="0 0 -0.135"/>
      <geometry>
        <mesh filename="package://dual_arm/robot_description/meshes/collision/wrist1.stl"/>
      </geometry>
    </collision>
    <inertial>
      <mass value="2.18"/>
      <origin rpy="0 0 0" xyz="0 0 0"/>
      <inertia ixx="0.0056816227273499996" ixy="0.0" ixz="0.0" iyy="0.0056816227273499996" iyz="0.0" izz="0.00613125"/>
    </inertial>
  </link>
  <link name="R_wrist_2_link">
    <visual>
      <origin rpy="0 0 0" xyz="0 0 -0.12"/>
      <geometry>
        <mesh filename="package://dual_arm/robot_description/meshes/visual/wrist2.dae"/>
      </geometry>
      <material name="LightGrey">
        <color rgba="0.7 0.7 0.7 1.0"/>
      </material>
    </visual>
    <collision>
      <origin rpy="0 0 0" xyz="0 0 -0.12"/>
      <geometry>
        <mesh filename="package://dual_arm/robot_description/meshes/collision/wrist2.stl"/>
      </geometry>
    </collision>
    <inertial>
      <mass value="2.033"/>
      <origin rpy="0 0 0" xyz="0 0 0"/>
      <inertia ixx="0.0052985041305975" ixy="0.0" ixz="0.0" iyy="0.0052985041305975" iyz="0.0" izz="0.0057178125"/>
    </inertial>
  </link>
  <link name="R_wrist_3_link">
    <visual>
      <origin rpy="1.5707963267948966 0 0" xyz="0 0 -0.1168"/>
      <geometry>
        <mesh filename="package://dual_arm/robot_description/meshes/visual/wrist3.dae"/>
      </geometry>
      <material name="LightGrey">
        <color rgba="0.7 0.7 0.7 1.0"/>
      </material>
    </visual>
    <collision>
      <origin rpy="1.5707963267948966 0 0" xyz="0 0 -0.1168"/>
      <geometry>
        <mesh filename="package://dual_arm/robot_description/meshes/collision/wrist3.stl"/>
      </geometry>
    </collision>
    <inertial>
      <mass value="0.907"/>
      <origin rpy="0 0 0" xyz="0.0 0.0 -0.025"/>
      <inertia ixx="0.0006481268240825001" ixy="0.0" ixz="0.0" iyy="0.0006481268240825001" iyz="0.0" izz="0.0009183374999999999"/>
    </inertial>
  </link>

  <joint name="R_shoulder_pan_joint" type="revolute">
    <parent link="R_base_link_inertia"/>
    <child link="R_shoulder_link"/>
    <origin rpy="0 0 0" xyz="0 0 0.1807"/>
    <axis xyz="0 0 1"/>
    <limit effort="330.0" lower="-6.283185307179586" upper="6.283185307179586" velocity="2.0943951023931953"/>
    <dynamics damping="0" friction="0"/>
  </joint>
  <joint name="R_shoulder_lift_joint" type="revolute">
    <parent link="R_shoulder_link"/>
    <child link="R_upper_arm_link"/>
    <origin rpy="1.5707963267948966 0 0" xyz="0 0 0"/>
    <axis xyz="0 0 1"/>
    <limit effort="330.0" lower="-6.283185307179586" upper="6.283185307179586" velocity="2.0943951023931953"/>
    <dynamics damping="0" friction="0"/>
  </joint>
  <joint name="R_elbow_joint" type="revolute">
    <parent link="R_upper_arm_link"/>
    <child link="R_forearm_link"/>
    <origin rpy="0 0 0" xyz="-0.4784 0 0"/>
    <axis xyz="0 0 1"/>
    <limit effort="150.0" lower="-3.141592653589793" upper="3.141592653589793" velocity="3.141592653589793"/>
    <dynamics damping="0" friction="0"/>
  </joint>
  <joint name="R_wrist_1_joint" type="revolute">
    <parent link="R_forearm_link"/>
    <child link="R_wrist_1_link"/>
    <origin rpy="0 0 0" xyz="-0.36 0 0.17415"/>
    <axis xyz="0 0 1"/>
    <limit effort="56.0" lower="-6.283185307179586" upper="6.283185307179586" velocity="3.141592653589793"/>
    <dynamics damping="0" friction="0"/>
  </joint>
  <joint name="R_wrist_2_joint" type="revolute">
    <parent link="R_wrist_1_link"/>
    <child link="R_wrist_2_link"/>
    <origin rpy="1.5707963267948966 0 0" xyz="0 -0.11985 -2.458164590756244e-11"/>
    <axis xyz="0 0 1"/>
    <limit effort="56.0" lower="-6.283185307179586" upper="6.283185307179586" velocity="3.141592653589793"/>
    <dynamics damping="0" friction="0"/>
  </joint>
  <joint name="R_wrist_3_joint" type="revolute">
    <parent link="R_wrist_2_link"/>
    <child link="R_wrist_3_link"/>
    <origin rpy="1.5707963267948966 3.141592653589793 3.141592653589793" xyz="0 0.11655 -2.390480459346185e-11"/>
    <axis xyz="0 0 1"/>
    <limit effort="56.0" lower="-6.283185307179586" upper="6.283185307179586" velocity="3.141592653589793"/>
    <dynamics damping="0" friction="0"/>
  </joint>



  <joint name="L_joint0" type="fixed">
    <parent link="mecanum_base"/>
    <child link="L_base_link"/>
    <origin rpy="-1.5707963267948966 3.141592653589793 0" xyz="0.458024331317477 0.145384104927055 1.2"/>
  </joint>
  <link name="L_base_link"/>
  <joint name="L_base_link-base_link_inertia" type="fixed">
    <parent link="L_base_link" />
    <child link="L_base_link_inertia" />
    <!-- 'base_link' is REP-103 aligned (so X+ forward), while the internal
          frames of the robot/controller have X+ pointing backwards.
          Use the joint between 'base_link' and 'base_link_inertia' (a dummy
          link/frame) to introduce the necessary rotation over Z (of pi rad).
    -->
    <origin xyz="0 0 0" rpy="0 0 -3.141592653589793" />
  </joint>
  <link name="L_base_link_inertia">
    <visual>
      <origin rpy="0 0 3.141592653589793" xyz="0 0 0"/>
      <geometry>
        <mesh filename="package://dual_arm/robot_description/meshes/visual/base.dae"/>
      </geometry>
      <material name="LightGrey">
        <color rgba="0.7 0.7 0.7 1.0"/>
      </material>
    </visual>
    <collision>
      <origin rpy="0 0 3.141592653589793" xyz="0 0 0"/>
      <geometry>
        <mesh filename="package://dual_arm/robot_description/meshes/collision/base.stl"/>
      </geometry>
    </collision>
    <inertial>
      <mass value="4.0"/>
      <origin rpy="0 0 0" xyz="0 0 0"/>
      <inertia ixx="0.0061063308908" ixy="0.0" ixz="0.0" iyy="0.0061063308908" iyz="0.0" izz="0.01125"/>
    </inertial>
  </link>
  <link name="L_shoulder_link">
    <visual>
      <origin rpy="0 0 3.141592653589793" xyz="0 0 0"/>
      <geometry>
        <mesh filename="package://dual_arm/robot_description/meshes/visual/shoulder.dae"/>
      </geometry>
      <material name="LightGrey">
        <color rgba="0.7 0.7 0.7 1.0"/>
      </material>
    </visual>
    <collision>
      <origin rpy="0 0 3.141592653589793" xyz="0 0 0"/>
      <geometry>
        <mesh filename="package://dual_arm/robot_description/meshes/collision/shoulder.stl"/>
      </geometry>
    </collision>
    <inertial>
      <mass value="7.369"/>
      <origin rpy="0 0 0" xyz="0 0 0"/>
      <inertia ixx="0.029819260655624295" ixy="0.0" ixz="0.0" iyy="0.029819260655624295" iyz="0.0" izz="0.020725312499999995"/>
    </inertial>
  </link>
  <link name="L_upper_arm_link">
    <visual>
      <origin rpy="1.5707963267948966 0 -1.5707963267948966" xyz="0 0 0.176"/>
      <geometry>
        <mesh filename="package://dual_arm/robot_description/meshes/visual/upperarm.dae"/>
      </geometry>
      <material name="LightGrey">
        <color rgba="0.7 0.7 0.7 1.0"/>
      </material>
    </visual>
    <collision>
      <origin rpy="1.5707963267948966 0 -1.5707963267948966" xyz="0 0 0.176"/>
      <geometry>
        <mesh filename="package://dual_arm/robot_description/meshes/collision/upperarm.stl"/>
      </geometry>
    </collision>
    <inertial>
      <mass value="10.45"/>
      <origin rpy="0 1.5707963267948966 0" xyz="-0.2392 0.0 0.175"/>
      <inertia ixx="0.21399985623335657" ixy="0.0" ixz="0.0" iyy="0.21399985623335657" iyz="0.0" izz="0.029390624999999997"/>
    </inertial>
  </link>
  <link name="L_forearm_link">
    <visual>
      <origin rpy="1.5707963267948966 0 -1.5707963267948966" xyz="0 0 0.04"/>
      <geometry>
        <mesh filename="package://dual_arm/robot_description/meshes/visual/forearm.dae"/>
      </geometry>
      <material name="LightGrey">
        <color rgba="0.7 0.7 0.7 1.0"/>
      </material>
    </visual>
    <collision>
      <origin rpy="1.5707963267948966 0 -1.5707963267948966" xyz="0 0 0.04"/>
      <geometry>
        <mesh filename="package://dual_arm/robot_description/meshes/collision/forearm.stl"/>
      </geometry>
    </collision>
    <inertial>
      <mass value="4.321"/>
      <origin rpy="0 1.5707963267948966 0" xyz="-0.18 0.0 0.04"/>
      <inertia ixx="0.052743185152717496" ixy="0.0" ixz="0.0" iyy="0.052743185152717496" iyz="0.0" izz="0.012152812499999997"/>
    </inertial>
  </link>
  <link name="L_wrist_1_link">
    <visual>
      <origin rpy="1.5707963267948966 0 0" xyz="0 0 -0.135"/>
      <geometry>
        <mesh filename="package://dual_arm/robot_description/meshes/visual/wrist1.dae"/>
      </geometry>
      <material name="LightGrey">
        <color rgba="0.7 0.7 0.7 1.0"/>
      </material>
    </visual>
    <collision>
      <origin rpy="1.5707963267948966 0 0" xyz="0 0 -0.135"/>
      <geometry>
        <mesh filename="package://dual_arm/robot_description/meshes/collision/wrist1.stl"/>
      </geometry>
    </collision>
    <inertial>
      <mass value="2.18"/>
      <origin rpy="0 0 0" xyz="0 0 0"/>
      <inertia ixx="0.0056816227273499996" ixy="0.0" ixz="0.0" iyy="0.0056816227273499996" iyz="0.0" izz="0.00613125"/>
    </inertial>
  </link>
  <link name="L_wrist_2_link">
    <visual>
      <origin rpy="0 0 0" xyz="0 0 -0.12"/>
      <geometry>
        <mesh filename="package://dual_arm/robot_description/meshes/visual/wrist2.dae"/>
      </geometry>
      <material name="LightGrey">
        <color rgba="0.7 0.7 0.7 1.0"/>
      </material>
    </visual>
    <collision>
      <origin rpy="0 0 0" xyz="0 0 -0.12"/>
      <geometry>
        <mesh filename="package://dual_arm/robot_description/meshes/collision/wrist2.stl"/>
      </geometry>
    </collision>
    <inertial>
      <mass value="2.033"/>
      <origin rpy="0 0 0" xyz="0 0 0"/>
      <inertia ixx="0.0052985041305975" ixy="0.0" ixz="0.0" iyy="0.0052985041305975" iyz="0.0" izz="0.0057178125"/>
    </inertial>
  </link>
  <link name="L_wrist_3_link">
    <visual>
      <origin rpy="1.5707963267948966 0 0" xyz="0 0 -0.1168"/>
      <geometry>
        <mesh filename="package://dual_arm/robot_description/meshes/visual/wrist3.dae"/>
      </geometry>
      <material name="LightGrey">
        <color rgba="0.7 0.7 0.7 1.0"/>
      </material>
    </visual>
    <collision>
      <origin rpy="1.5707963267948966 0 0" xyz="0 0 -0.1168"/>
      <geometry>
        <mesh filename="package://dual_arm/robot_description/meshes/collision/wrist3.stl"/>
      </geometry>
    </collision>
    <inertial>
      <mass value="0.907"/>
      <origin rpy="0 0 0" xyz="0.0 0.0 -0.025"/>
      <inertia ixx="0.0006481268240825001" ixy="0.0" ixz="0.0" iyy="0.0006481268240825001" iyz="0.0" izz="0.0009183374999999999"/>
    </inertial>
  </link>

  <joint name="L_shoulder_pan_joint" type="revolute">
    <parent link="L_base_link_inertia"/>
    <child link="L_shoulder_link"/>
    <origin rpy="0 0 0" xyz="0 0 0.1807"/>
    <axis xyz="0 0 1"/>
    <limit effort="330.0" lower="-6.283185307179586" upper="6.283185307179586" velocity="2.0943951023931953"/>
    <dynamics damping="0" friction="0"/>
  </joint>
  <joint name="L_shoulder_lift_joint" type="revolute">
    <parent link="L_shoulder_link"/>
    <child link="L_upper_arm_link"/>
    <origin rpy="1.5707963267948966 0 0" xyz="0 0 0"/>
    <axis xyz="0 0 1"/>
    <limit effort="330.0" lower="-6.283185307179586" upper="6.283185307179586" velocity="2.0943951023931953"/>
    <dynamics damping="0" friction="0"/>
  </joint>
  <joint name="L_elbow_joint" type="revolute">
    <parent link="L_upper_arm_link"/>
    <child link="L_forearm_link"/>
    <origin rpy="0 0 0" xyz="-0.4784 0 0"/>
    <axis xyz="0 0 1"/>
    <limit effort="150.0" lower="-3.141592653589793" upper="3.141592653589793" velocity="3.141592653589793"/>
    <dynamics damping="0" friction="0"/>
  </joint>
  <joint name="L_wrist_1_joint" type="revolute">
    <parent link="L_forearm_link"/>
    <child link="L_wrist_1_link"/>
    <origin rpy="0 0 0" xyz="-0.36 0 0.17415"/>
    <axis xyz="0 0 1"/>
    <limit effort="56.0" lower="-6.283185307179586" upper="6.283185307179586" velocity="3.141592653589793"/>
    <dynamics damping="0" friction="0"/>
  </joint>
  <joint name="L_wrist_2_joint" type="revolute">
    <parent link="L_wrist_1_link"/>
    <child link="L_wrist_2_link"/>
    <origin rpy="1.5707963267948966 0 0" xyz="0 -0.11985 -2.458164590756244e-11"/>
    <axis xyz="0 0 1"/>
    <limit effort="56.0" lower="-6.283185307179586" upper="6.283185307179586" velocity="3.141592653589793"/>
    <dynamics damping="0" friction="0"/>
  </joint>
  <joint name="L_wrist_3_joint" type="revolute">
    <parent link="L_wrist_2_link"/>
    <child link="L_wrist_3_link"/>
    <origin rpy="1.5707963267948966 3.141592653589793 3.141592653589793" xyz="0 0.11655 -2.390480459346185e-11"/>
    <axis xyz="0 0 1"/>
    <limit effort="56.0" lower="-6.283185307179586" upper="6.283185307179586" velocity="3.141592653589793"/>
    <dynamics damping="0" friction="0"/>
  </joint>

  <transmission name="x_dir_trans">
    <type>transmission_interface/SimpleTransmission</type>
    <joint name="x_dir_joint">
      <hardwareInterface>hardware_interface/VelocityJointInterface</hardwareInterface>
    </joint>
    <actuator name="x_dir_motor">
      <mechanicalReduction>1</mechanicalReduction>
    </actuator>
  </transmission>
  <gazebo reference="x_dir_link">
    <selfCollide>false</selfCollide>
    <turnGravityOff>true</turnGravityOff>
  </gazebo>
  <transmission name="y_dir_trans">
    <type>transmission_interface/SimpleTransmission</type>
    <joint name="y_dir_joint">
      <hardwareInterface>hardware_interface/VelocityJointInterface</hardwareInterface>
    </joint>
    <actuator name="y_dir_motor">
      <mechanicalReduction>1</mechanicalReduction>
    </actuator>
  </transmission>
  <gazebo reference="y_dir_link">
    <selfCollide>false</selfCollide>
    <turnGravityOff>true</turnGravityOff>
  </gazebo>
  <transmission name="z_dir_trans">
    <type>transmission_interface/SimpleTransmission</type>
    <joint name="z_dir_joint">
      <hardwareInterface>hardware_interface/VelocityJointInterface</hardwareInterface>
    </joint>
    <actuator name="z_dir_motor">
      <mechanicalReduction>1</mechanicalReduction>
    </actuator>
  </transmission>
  <gazebo reference="mecanum_base">
    <selfCollide>false</selfCollide>
    <turnGravityOff>true</turnGravityOff>
  </gazebo>

  <transmission name="R_shoulder_pan_trans">
    <type>transmission_interface/SimpleTransmission</type>
    <joint name="R_shoulder_pan_joint">
      <hardwareInterface>hardware_interface/VelocityJointInterface</hardwareInterface>
    </joint>
    <actuator name="R_shoulder_pan_motor">
      <mechanicalReduction>1</mechanicalReduction>
    </actuator>
  </transmission>
  <transmission name="R_shoulder_lift_trans">
    <type>transmission_interface/SimpleTransmission</type>
    <joint name="R_shoulder_lift_joint">
      <hardwareInterface>hardware_interface/VelocityJointInterface</hardwareInterface>
    </joint>
    <actuator name="R_shoulder_lift_motor">
      <mechanicalReduction>1</mechanicalReduction>
    </actuator>
  </transmission>
  <transmission name="R_elbow_trans">
    <type>transmission_interface/SimpleTransmission</type>
    <joint name="R_elbow_joint">
      <hardwareInterface>hardware_interface/VelocityJointInterface</hardwareInterface>
    </joint>
    <actuator name="R_elbow_motor">
      <mechanicalReduction>1</mechanicalReduction>
    </actuator>
  </transmission>
  <transmission name="R_wrist_1_trans">
    <type>transmission_interface/SimpleTransmission</type>
    <joint name="R_wrist_1_joint">
      <hardwareInterface>hardware_interface/VelocityJointInterface</hardwareInterface>
    </joint>
    <actuator name="R_wrist_1_motor">
      <mechanicalReduction>1</mechanicalReduction>
    </actuator>
  </transmission>
  <transmission name="R_wrist_2_trans">
    <type>transmission_interface/SimpleTransmission</type>
    <joint name="R_wrist_2_joint">
      <hardwareInterface>hardware_interface/VelocityJointInterface</hardwareInterface>
    </joint>
    <actuator name="R_wrist_2_motor">
      <mechanicalReduction>1</mechanicalReduction>
    </actuator>
  </transmission>
  <transmission name="R_wrist_3_trans">
    <type>transmission_interface/SimpleTransmission</type>
    <joint name="R_wrist_3_joint">
      <hardwareInterface>hardware_interface/VelocityJointInterface</hardwareInterface>
    </joint>
    <actuator name="R_wrist_3_motor">
      <mechanicalReduction>1</mechanicalReduction>
    </actuator>
  </transmission>

  <transmission name="L_shoulder_pan_trans">
    <type>transmission_interface/SimpleTransmission</type>
    <joint name="L_shoulder_pan_joint">
      <hardwareInterface>hardware_interface/VelocityJointInterface</hardwareInterface>
    </joint>
    <actuator name="L_shoulder_pan_motor">
      <mechanicalReduction>1</mechanicalReduction>
    </actuator>
  </transmission>
  <transmission name="L_shoulder_lift_trans">
    <type>transmission_interface/SimpleTransmission</type>
    <joint name="L_shoulder_lift_joint">
      <hardwareInterface>hardware_interface/VelocityJointInterface</hardwareInterface>
    </joint>
    <actuator name="L_shoulder_lift_motor">
      <mechanicalReduction>1</mechanicalReduction>
    </actuator>
  </transmission>
  <transmission name="L_elbow_trans">
    <type>transmission_interface/SimpleTransmission</type>
    <joint name="L_elbow_joint">
      <hardwareInterface>hardware_interface/VelocityJointInterface</hardwareInterface>
    </joint>
    <actuator name="L_elbow_motor">
      <mechanicalReduction>1</mechanicalReduction>
    </actuator>
  </transmission>
  <transmission name="L_wrist_1_trans">
    <type>transmission_interface/SimpleTransmission</type>
    <joint name="L_wrist_1_joint">
      <hardwareInterface>hardware_interface/VelocityJointInterface</hardwareInterface>
    </joint>
    <actuator name="L_wrist_1_motor">
      <mechanicalReduction>1</mechanicalReduction>
    </actuator>
  </transmission>
  <transmission name="L_wrist_2_trans">
    <type>transmission_interface/SimpleTransmission</type>
    <joint name="L_wrist_2_joint">
      <hardwareInterface>hardware_interface/VelocityJointInterface</hardwareInterface>
    </joint>
    <actuator name="L_wrist_2_motor">
      <mechanicalReduction>1</mechanicalReduction>
    </actuator>
  </transmission>
  <transmission name="L_wrist_3_trans">
    <type>transmission_interface/SimpleTransmission</type>
    <joint name="L_wrist_3_joint">
      <hardwareInterface>hardware_interface/VelocityJointInterface</hardwareInterface>
    </joint>
    <actuator name="L_wrist_3_motor">
      <mechanicalReduction>1</mechanicalReduction>
    </actuator>
  </transmission>

  <gazebo reference="R_shoulder_link">
    <selfCollide>false</selfCollide>
    <turnGravityOff>true</turnGravityOff>
  </gazebo>
  <gazebo reference="R_upper_arm_link">
    <selfCollide>false</selfCollide>
    <turnGravityOff>true</turnGravityOff>
  </gazebo>
  <gazebo reference="R_forearm_link">
    <selfCollide>false</selfCollide>
    <turnGravityOff>true</turnGravityOff>
  </gazebo>
  <gazebo reference="R_wrist_1_link">
    <selfCollide>false</selfCollide>
    <turnGravityOff>true</turnGravityOff>
  </gazebo>
  <gazebo reference="R_wrist_3_link">
    <selfCollide>false</selfCollide>
    <turnGravityOff>true</turnGravityOff>
  </gazebo>
  <gazebo reference="R_wrist_2_link">
    <selfCollide>false</selfCollide>
    <turnGravityOff>true</turnGravityOff>
  </gazebo>
  <gazebo reference="R_base_link_inertia">
    <selfCollide>false</selfCollide>
    <turnGravityOff>true</turnGravityOff>
  </gazebo>
  <gazebo reference="L_shoulder_link">
    <selfCollide>false</selfCollide>
    <turnGravityOff>true</turnGravityOff>
  </gazebo>
  <gazebo reference="L_upper_arm_link">
    <selfCollide>false</selfCollide>
    <turnGravityOff>true</turnGravityOff>
  </gazebo>
  <gazebo reference="L_forearm_link">
    <selfCollide>false</selfCollide>
    <turnGravityOff>true</turnGravityOff>
  </gazebo>
  <gazebo reference="L_wrist_1_link">
    <selfCollide>false</selfCollide>
    <turnGravityOff>true</turnGravityOff>
  </gazebo>
  <gazebo reference="L_wrist_3_link">
    <selfCollide>false</selfCollide>
    <turnGravityOff>true</turnGravityOff>
  </gazebo>
  <gazebo reference="L_wrist_2_link">
    <selfCollide>false</selfCollide>
    <turnGravityOff>true</turnGravityOff>
  </gazebo>
  <gazebo reference="L_base_link_inertia">
    <selfCollide>false</selfCollide>
    <turnGravityOff>true</turnGravityOff>
  </gazebo>
</robot>

